Workbook

Sheet Summary
A2: Family Name | B2: Portfolio Name | C2: Asset Class | D2: Advisors | E2: Asset Name | F2: ISIN
A3: DAJ | B3: AIF | C3: AIF | D3: 360 One | E3: Mt.K Capital Fund Category II
A4: DAJ | B4: Debt MF | C4: Mutual Funds | D4: ARTHYA | E4: BANDHAN Dynamic Bond Fund-Direct Plan-Growth | F4: INF194K01N63
A5: DAJ | B5: Liquid MF | C5: Mutual Funds | D5: KOTAK | E5: Kotak Liquid - Growth - Direct | F5: INF174K01NE8
A6: DAJ | B6: Equity MF | C6: Mutual Funds | D6: ARTHYA | E6: HDFC Focused Fund - Growth Option - Direct Plan | F6: INF179K01VK7
A7: DAJ | B7: Equity MF | C7: Mutual Funds | D7: KOTAK | E7: HDFC Focused Fund - Growth Option - Direct Plan\ | F7: INF179K01VK7
A8: DAJ | B8: CARNELIAN | C8: Equity Stocks | D8: ARTHYA | E8: Aditya Birla Capital | F8: INE674K01013
A9: DAJ | B9: CARNELIAN | C9: Equity Stocks | D9: ARTHYA | E9: Aurobindo Pharma | F9: INE406A01037
A10: DAJ | B10: CARNELIAN | C10: Equity Stocks | D10: ARTHYA | E10: Bharti Airtel | F10: INE397D01024
A11: DAJ | B11: CARNELIAN | C11: Equity Stocks | D11: ARTHYA | E11: Biocon Limited | F11: INE376G01013
A12: DAJ | B12: CARNELIAN | C12: Equity Stocks | D12: ARTHYA | E12: Canara Bank | F12: INE476A01022
A13: DAJ | B13: CARNELIAN | C13: Equity Stocks | D13: ARTHYA | E13: Cyient Limited | F13: INE136B01020
A14: DAJ | B14: CARNELIAN | C14: Equity Stocks | D14: ARTHYA | E14: Dr Lal Pathlabs | F14: INE600L01024
A15: DAJ | B15: CARNELIAN | C15: Equity Stocks | D15: ARTHYA | E15: Endurance Technologies | F15: INE913H01037
... A44: DAJ | B44: InvITs | C44: REITs/InvITs | D44: KOTAK | E44: Cube Highways InvIT | F44: INE0NR623014
A45: DAJ | B45: Unlisted Holdings | C45: Alternate | D45: ARTHYA | E45: Credilio Financial Technologies Private Limited CCPS
A46: DAJ | B46: Bank | C46: Bank | D46: DIRECT | E46: Kotak Savings A/c
A47: DAJ | B47: LRS | C47: LRS | D47: 360 One | E47: Ashoka WhiteOak Emerging Markets Equity Ex India Fund Class A
A51: DJT | B51: BUOYANT | C51: Equity Stocks | D51: 360 One | E51: Archean Chemical Industries | F51: INE128X01021
A52: DJT | B52: BUOYANT | C52: Equity Stocks | D52: 360 One | E52: AXIS Bank | F52: INE238A01034
A53: DJT | B53: BUOYANT | C53: Equity Stocks | D53: 360 One | E53: Bajaj Auto | F53: INE917I01010
A54: DJT | B54: BUOYANT | C54: Equity Stocks | D54: 360 One | E54: Bajaj Finance | F54: INE296A01032
A55: DJT | B55: BUOYANT | C55: Equity Stocks | D55: 360 One | E55: Bharti Airtel | F55: INE397D01024
A56: DJT | B56: BUOYANT | C56: Equity Stocks | D56: 360 One | E56: Britannia Industries | F56: INE216A01030
A57: DJT | B57: BUOYANT | C57: Equity Stocks | D57: 360 One | E57: Dalmia Bharat | F57: INE00R701025
A58: DJT | B58: BUOYANT | C58: Equity Stocks | D58: 360 One | E58: Dilip Buildcon | F58: INE917M01012
A59: DJT | B59: BUOYANT | C59: Equity Stocks | D59: 360 One | E59: Dr. Reddy's Laboratories | F59: INE089A01031
A60: DJT | B60: BUOYANT | C60: Equity Stocks | D60: 360 One | E60: Glenmark Pharmaceuticals | F60: INE935A01035
A61: DJT | B61: BUOYANT | C61: Equity Stocks | D61: 360 One | E61: Granules India | F61: INE101D01020
A62: DJT | B62: BUOYANT | C62: Equity Stocks | D62: 360 One | E62: Hindustan Unilever | F62: INE030A01027
... A81: DJT | B81: BUOYANT | C81: Equity Stocks | D81: 360 One | E81: VIP Industries | F81: INE054A01027
A82: DJT | B82: AIF | C82: AIF | D82: DIRECT | E82: Alchemy Long Term Venture Fund - Series 2
A83: DJT | B83: Debt MF | C83: Mutual Funds | D83: ARTHYA | E83: BANDHAN Dynamic Bond Fund-Direct Plan-Growth | F83: INF194K01N63
A84: DJT | B84: Liquid MF | C84: Mutual Funds | D84: KOTAK | E84: ICICI Prudential Liquid Fund - Direct Plan - Growth | F84: INF109K01Q49
A85: DJT | B85: Equity MF | C85: Mutual Funds | D85: ARTHYA | E85: HDFC Focused Fund - Growth Option - Direct Plan | F85: INF179K01VK7
A86: DJT | B86: Arbitrage MF | C86: Mutual Funds | D86: KOTAK | E86: ICICI Prudential Arbitrage Fund - Direct Plan - Growth | F86: INF109K016O4
A87: DJT | B87: REITs | C87: REITs/InvITs | D87: ARTHYA | E87: Knowledge Realty Trust | F87: INE1JAR25012
A88: DJT | B88: Direct Equity | C88: Equity Stocks | D88: DIRECT | E88: Bajaj Finance | F88: INE296A01032
A89: DJT | B89: Direct Equity | C89: Equity Stocks | D89: DIRECT | E89: Divi's Laboratories | F89: INE361B01024
A90: DJT | B90: Direct Equity | C90: Equity Stocks | D90: DIRECT | E90: HCL Technologies | F90: INE860A01027
...

Sheet Detail
A2: Family Name | B2: Portfolio Name | C2: Asset Class | D2: Advisors | E2: Asset Name | F2: ISIN | G2: Quantity | H2: Avg. Purchase Price | I2: Amount Invested | J2: Current Price | K2: Current Value
A3: DAJ | B3: AIF | C3: AIF | D3: 360 One | E3: Mt.K Capital Fund Category II | G3: 215989.2 | H3: =I3/G3 -> 95.645571 | I3: 20658410 | J3: 126.5739 | K3: 16515153
A4: DAJ | B4: Debt MF | C4: Mutual Funds | D4: ARTHYA | E4: BANDHAN Dynamic Bond Fund-Direct Plan-Growth | F4: INF194K01N63 | G4: 2238333.7 | H4: 31.27 | I4: 70000000 | J4: 40.5573 | K4: 90780772
A5: DAJ | B5: Liquid MF | C5: Mutual Funds | D5: KOTAK | E5: Kotak Liquid - Growth - Direct | F5: INF174K01NE8 | G5: 7523.049 | H5: 5629.13 | I5: 42348194 | J5: 5713.3459 | K5: 42981781
A6: DAJ | B6: Equity MF | C6: Mutual Funds | D6: ARTHYA | E6: HDFC Focused Fund - Growth Option - Direct Plan | F6: INF179K01VK7 | G6: 5091.381 | H6: 267.7 | I6: 1362979.9 | J6: 270.406 | K6: 1376740
A7: DAJ | B7: Equity MF | C7: Mutual Funds | D7: KOTAK | E7: HDFC Focused Fund - Growth Option - Direct Plan\ | F7: INF179K01VK7 | G7: 25771.215 | H7: 268.81 | I7: 6927520.2 | J7: 270.406 | K7: 6968691.2
A8: DAJ | B8: CARNELIAN | C8: Equity Stocks | D8: ARTHYA | E8: Aditya Birla Capital | F8: INE674K01013 | G8: 5803 | H8: 350.11 | I8: 2031691.2 | J8: 396.2 | K8: 2299148.6
A9: DAJ | B9: CARNELIAN | C9: Equity Stocks | D9: ARTHYA | E9: Aurobindo Pharma | F9: INE406A01037 | G9: 433 | H9: 1407.78 | I9: 609568.55 | J9: 1643.7 | K9: 711722.1
A10: DAJ | B10: CARNELIAN | C10: Equity Stocks | D10: ARTHYA | E10: Bharti Airtel | F10: INE397D01024 | G10: 406 | H10: 1966.5 | I10: 798399.98 | J10: 1986.1 | K10: 806356.6
A11: DAJ | B11: CARNELIAN | C11: Equity Stocks | D11: ARTHYA | E11: Biocon Limited | F11: INE376G01013 | G11: 4038 | H11: 358.28 | I11: 1446751.2 | J11: 410.85 | K11: 1659012.3
A12: DAJ | B12: CARNELIAN | C12: Equity Stocks | D12: ARTHYA | E12: Canara Bank | F12: INE476A01022 | G12: 4458 | H12: 138.05 | I12: 615433.86 | J12: 129.8 | K12: 578648.4
A13: DAJ | B13: CARNELIAN | C13: Equity Stocks | D13: ARTHYA | E13: Cyient Limited | F13: INE136B01020 | G13: 119 | H13: 885.11 | I13: 105328.34 | J13: 849.05 | K13: 101036.95
A14: DAJ | B14: CARNELIAN | C14: Equity Stocks | D14: ARTHYA | E14: Dr Lal Pathlabs | F14: INE600L01024 | G14: 515 | H14: 1613.65 | I14: 831030.51 | J14: 1898.9 | K14: 977933.5
A15: DAJ | B15: CARNELIAN | C15: Equity Stocks | D15: ARTHYA | E15: Endurance Technologies | F15: INE913H01037 | G15: 325 | H15: 2391.62 | I15: 777277.83 | J15: 3003 | K15: 975975
... A44: DAJ | B44: InvITs | C44: REITs/InvITs | D44: KOTAK | E44: Cube Highways InvIT | F44: INE0NR623014 | G44: 350000 | H44: 146.19 | I44: 51167034 | J44: 159.89 | K44: 55961500
A45: DAJ | B45: Unlisted Holdings | C45: Alternate | D45: ARTHYA | E45: Credilio Financial Technologies Private Limited CCPS | G45: 83 | H45: 120880 | I45: 10033040 | J45: 120880 | K45: 10033040
A46: DAJ | B46: Bank | C46: Bank | D46: DIRECT | E46: Kotak Savings A/c | I46: 1629616.3 | K46: 1629616.3
A47: DAJ | B47: LRS | C47: LRS | D47: 360 One | E47: Ashoka WhiteOak Emerging Markets Equity Ex India Fund Class A | G47: 1108.805 | H47: 177.22 | I47: 17700413 | J47: 20536.513 | K47: 22770988
A51: DJT | B51: BUOYANT | C51: Equity Stocks | D51: 360 One | E51: Archean Chemical Industries | F51: INE128X01021 | G51: 3169 | H51: 520.92 | I51: 1650780.3 | J51: 511.8 | K51: 1621894.2
A52: DJT | B52: BUOYANT | C52: Equity Stocks | D52: 360 One | E52: AXIS Bank | F52: INE238A01034 | G52: 3480 | H52: 1249.17 | I52: 4347124.6 | J52: 1215.7 | K52: 4230636
A53: DJT | B53: BUOYANT | C53: Equity Stocks | D53: 360 One | E53: Bajaj Auto | F53: INE917I01010 | G53: 142 | H53: 9033.19 | I53: 1282712.9 | J53: 11670 | K53: 1657140
A54: DJT | B54: BUOYANT | C54: Equity Stocks | D54: 360 One | E54: Bajaj Finance | F54: INE296A01032 | G54: 2934 | H54: 879.1 | I54: 2579285 | J54: 1089.8 | K54: 3197473.2
A55: DJT | B55: BUOYANT | C55: Equity Stocks | D55: 360 One | E55: Bharti Airtel | F55: INE397D01024 | G55: 1082 | H55: 1833.2 | I55: 1983518.9 | J55: 1986.1 | K55: 2148960.2
A56: DJT | B56: BUOYANT | C56: Equity Stocks | D56: 360 One | E56: Britannia Industries | F56: INE216A01030 | G56: 300 | H56: 5624.21 | I56: 1687262.9 | J56: 5507 | K56: 1652100
A57: DJT | B57: BUOYANT | C57: Equity Stocks | D57: 360 One | E57: Dalmia Bharat | F57: INE00R701025 | G57: 1058 | H57: 1897.98 | I57: 2008060.6 | J57: 1847 | K57: 1954126
A58: DJT | B58: BUOYANT | C58: Equity Stocks | D58: 360 One | E58: Dilip Buildcon | F58: INE917M01012 | G58: 3630 | H58: 417.96 | I58: 1517177.4 | J58: 412.9 | K58: 1498827
A59: DJT | B59: BUOYANT | C59: Equity Stocks | D59: 360 One | E59: Dr. Reddy's Laboratories | F59: INE089A01031 | G59: 680 | H59: 1319.77 | I59: 897442.94 | J59: 1190.4 | K59: 809472
A60: DJT | B60: BUOYANT | C60: Equity Stocks | D60: 360 One | E60: Glenmark Pharmaceuticals | F60: INE935A01035 | G60: 577 | H60: 2162.8 | I60: 1247935.1 | J60: 2305.4 | K60: 1330215.8
A61: DJT | B61: BUOYANT | C61: Equity Stocks | D61: 360 One | E61: Granules India | F61: INE101D01020 | G61: 2372 | H61: 604.43 | I61: 1433711.4 | J61: 850.25 | K61: 2016793
A62: DJT | B62: BUOYANT | C62: Equity Stocks | D62: 360 One | E62: Hindustan Unilever | F62: INE030A01027 | G62: 940 | H62: 2177.07 | I62: 2046449.8 | J62: 2061 | K62: 1937340
... A81: DJT | B81: BUOYANT | C81: Equity Stocks | D81: 360 One | E81: VIP Industries | F81: INE054A01027 | G81: 2384 | H81: 337.68 | I81: 805019.36 | J81: 295.15 | K81: 703637.6
A82: DJT | B82: AIF | C82: AIF | D82: DIRECT | E82: Alchemy Long Term Venture Fund - Series 2 | G82: 379504.77 | H82: 98.81 | I82: 37498125 | J82: 0 | K82: 37989680
A83: DJT | B83: Debt MF | C83: Mutual Funds | D83: ARTHYA | E83: BANDHAN Dynamic Bond Fund-Direct Plan-Growth | F83: INF194K01N63 | G83: 319761.96 | H83: 31.27 | I83: 10000000 | J83: 40.5573 | K83: 12968682
A84: DJT | B84: Liquid MF | C84: Mutual Funds | D84: KOTAK | E84: ICICI Prudential Liquid Fund - Direct Plan - Growth | F84: INF109K01Q49 | G84: 171419.64 | H84: 411.27 | I84: 70500000 | J84: 418.4641 | K84: 71732966
A85: DJT | B85: Equity MF | C85: Mutual Funds | D85: ARTHYA | E85: HDFC Focused Fund - Growth Option - Direct Plan | F85: INF179K01VK7 | G85: 242899.53 | H85: 223.66 | I85: 54327649 | J85: 270.406 | K85: 65681490
A86: DJT | B86: Arbitrage MF | C86: Mutual Funds | D86: KOTAK | E86: ICICI Prudential Arbitrage Fund - Direct Plan - Growth | F86: INF109K016O4 | G86: 102383.36 | H86: 37.51 | I86: 3839906.9 | J86: 39.4944 | K86: 4043569.3
A87: DJT | B87: REITs | C87: REITs/InvITs | D87: ARTHYA | E87: Knowledge Realty Trust | F87: INE1JAR25012 | G87: 86700 | H87: 99.51 | I87: 8627343.6 | J87: 115.73 | K87: 10033791
A88: DJT | B88: Direct Equity | C88: Equity Stocks | D88: DIRECT | E88: Bajaj Finance | F88: INE296A01032 | G88: 4550 | H88: 600.86 | I88: 2733912.6 | J88: 1089.8 | K88: 4958590
A89: DJT | B89: Direct Equity | C89: Equity Stocks | D89: DIRECT | E89: Divi's Laboratories | F89: INE361B01024 | G89: 637 | H89: 3666.17 | I89: 2335353.1 | J89: 8498 | K89: 5413226
A90: DJT | B90: Direct Equity | C90: Equity Stocks | D90: DIRECT | E90: HCL Technologies | F90: INE860A01027 | G90: 2620 | H90: 956.05 | I90: 2504849 | J90: 1334.4 | K90: 3496128
...

Sheet Transactions
A1: Family Name | B1: Asset Class | C1: Sub Class | D1: Asset Name | E1: Underlying | F1: Advisors | G1: ISIN | H1: Date | I1: Trans. Type | J1: Quantity | K1: Price | L1: Amount
A2: DAJ | B2: Equity | C2: Equity PMS | D2: Carnelian Capital Compounder Strategy | E2: Bharti Airtel | F2: ARTHYA | G2: =+VLOOKUP(E2,Summary!$E$3:$F$47,2,0) -> INE397D01024 | H2: 46239 | I2: Buy | J2: 198 | K2: 1969.9533 | L2: 390323.79
A3: DAJ | B3: Equity | C3: Equity PMS | D3: Carnelian Capital Compounder Strategy | E3: Bharti Airtel | F3: ARTHYA | G3: =+VLOOKUP(E3,Summary!$E$3:$F$47,2,0) -> INE397D01024 | H3: 46234 | I3: Buy | J3: 208 | K3: 1960.9243 | L3: 408076.19
A4: DAJ | B4: Equity | C4: Equity PMS | D4: Carnelian Capital Compounder Strategy | E4: Delhivery | F4: ARTHYA | G4: INE148O01028 | H4: 46234 | I4: Sell | J4: 278 | K4: 476.5 | L4: 132400.78
A5: DAJ | B5: Equity | C5: Equity PMS | D5: Carnelian Capital Compounder Strategy | E5: Delhivery | F5: ARTHYA | G5: INE148O01028 | H5: 46232 | I5: Sell | J5: 626 | K5: 472.7459 | L5: 295791.01
A6: DAJ | B6: Equity | C6: Equity PMS | D6: Carnelian Capital Compounder Strategy | E6: Sun Pharmaceutical | F6: ARTHYA | G6: =+VLOOKUP(E6,Summary!$E$3:$F$47,2,0) -> INE044A01036 | H6: 46232 | I6: Buy | J6: 34 | K6: 1970.9938 | L6: 67047.29
A7: DAJ | B7: Equity | C7: Equity PMS | D7: Carnelian Capital Compounder Strategy | E7: Sun Pharmaceutical | F7: ARTHYA | G7: =+VLOOKUP(E7,Summary!$E$3:$F$47,2,0) -> INE044A01036 | H7: 46231 | I7: Buy | J7: 89 | K7: 1984.6671 | L7: 176723.68
A8: DAJ | B8: Equity | C8: Equity PMS | D8: Carnelian Capital Compounder Strategy | E8: Pidilite Industries | F8: ARTHYA | G8: INE318A01026 | H8: 46230 | I8: Sell | J8: 151 | K8: 1596 | L8: 240876.26
A9: DAJ | B9: Equity | C9: Equity PMS | D9: Carnelian Capital Compounder Strategy | E9: Sun Pharmaceutical | F9: ARTHYA | G9: =+VLOOKUP(E9,Summary!$E$3:$F$47,2,0) -> INE044A01036 | H9: 46230 | I9: Buy | J9: 193 | K9: 1974.5437 | L9: 381277.46
A10: DAJ | B10: Equity | C10: Equity PMS | D10: Carnelian Capital Compounder Strategy | E10: Dr Lal Pathlabs | F10: ARTHYA | G10: =+VLOOKUP(E10,Summary!$E$3:$F$47,2,0) -> INE600L01024 | H10: 46227 | I10: Buy | J10: 14 | K10: 1722.4807 | L10: 24126.79
A11: DAJ | B11: Equity | C11: Equity PMS | D11: Carnelian Capital Compounder Strategy | E11: Pidilite Industries | F11: ARTHYA | G11: INE318A01026 | H11: 46227 | I11: Sell | J11: 285 | K11: 1570.5679 | L11: 447388.04
A12: DAJ | B12: Equity | C12: Equity PMS | D12: Carnelian Capital Compounder Strategy | E12: Bandhan Bank | F12: ARTHYA | G12: INE545U01014 | H12: 46226 | I12: Sell | J12: 861 | K12: 167.7673 | L12: 144346.53
A13: DAJ | B13: Equity | C13: Equity PMS | D13: Carnelian Capital Compounder Strategy | E13: Bandhan Bank | F13: ARTHYA | G13: INE545U01014 | H13: 46225 | I13: Sell | J13: 1081 | K13: 182.0485 | L13: 196696.05
A14: DAJ | B14: Equity | C14: Equity PMS | D14: Carnelian Capital Compounder Strategy | E14: Kalyan Jewellers India | F14: ARTHYA | G14: =+VLOOKUP(E14,Summary!$E$3:$F$47,2,0) -> INE303R01014 | H14: 46216 | I14: Buy | J14: 512 | K14: 500.0107 | L14: 256261.48
A15: DAJ | B15: Equity | C15: Equity PMS | D15: Carnelian Capital Compounder Strategy | E15: Tata Technologies | F15: ARTHYA | G15: =+VLOOKUP(E15,Summary!$E$3:$F$47,2,0) -> INE142M01025 | H15: 46212 | I15: Buy | J15: 150 | K15: 715.097 | L15: 107318.18
A16: DAJ | B16: Equity | C16: Equity PMS | D16: Carnelian Capital Compounder Strategy | E16: Cyient Limited | F16: ARTHYA | G16: =+VLOOKUP(E16,Summary!$E$3:$F$47,2,0) -> INE136B01020 | H16: 46210 | I16: Sell | J16: 37 | K16: 1125 | L16: 41562.19
A17: DAJ | B17: Equity | C17: Equity PMS | D17: Carnelian Capital Compounder Strategy | E17: Persistent Systems | F17: ARTHYA | G17: =+VLOOKUP(E17,Summary!$E$3:$F$47,2,0) -> INE262H01021 | H17: 46206 | I17: Buy | J17: 68 | K17: 4684.9996 | L17: 318898.55
A18: DAJ | B18: Equity | C18: Equity PMS | D18: Carnelian Capital Compounder Strategy | E18: Larsen & Toubro | F18: ARTHYA | G18: =+VLOOKUP(E18,Summary!$E$3:$F$47,2,0) -> INE018A01030 | H18: 46189 | I18: Buy | J18: 41 | K18: 4221.54 | L18: 173169.76
A19: DAJ | B19: Equity | C19: Equity PMS | D19: Carnelian Capital Compounder Strategy | E19: Tata Technologies | F19: ARTHYA | G19: =+VLOOKUP(E19,Summary!$E$3:$F$47,2,0) -> INE142M01025 | H19: 46188 | I19: Buy | J19: 513 | K19: 770.2931 | L19: 395357.92
A20: DAJ | B20: Equity | C20: Equity PMS | D20: Carnelian Capital Compounder Strategy | E20: Canara Bank | F20: ARTHYA | G20: =+VLOOKUP(E20,Summary!$E$3:$F$47,2,0) -> INE476A01022 | H20: 46185 | I20: Buy | J20: 71 | K20: 131.6137 | L20: 9349.24
A21: DAJ | B21: Equity | C21: Equity PMS | D21: Carnelian Capital Compounder Strategy | E21: Delhivery | F21: ARTHYA | G21: INE148O01028 | H21: 46185 | I21: Buy | J21: 15 | K21: 440.912 | L21: 6616.99
A22: DAJ | B22: Equity | C22: Equity PMS | D22: Carnelian Capital Compounder Strategy | E22: Larsen & Toubro | F22: ARTHYA | G22: =+VLOOKUP(E22,Summary!$E$3:$F$47,2,0) -> INE018A01030 | H22: 46185 | I22: Buy | J22: 4 | K22: 4043.0325 | L22: 16180.22
A23: DAJ | B23: Equity | C23: Equity PMS | D23: Carnelian Capital Compounder Strategy | E23: LTM Limited | F23: ARTHYA | G23: =+VLOOKUP(E23,Summary!$E$3:$F$47,2,0) -> INE214T01019 | H23: 46185 | I23: Buy | J23: 5 | K23: 3841.962 | L23: 19219.41
A24: DAJ | B24: Equity | C24: Equity PMS | D24: Carnelian Capital Compounder Strategy | E24: Max Financial Services | F24: ARTHYA | G24: =+VLOOKUP(E24,Summary!$E$3:$F$47,2,0) -> INE180A01020 | H24: 46185 | I24: Buy | J24: 16 | K24: 1577.1131 | L24: 25246.43
A25: DAJ | B25: Equity | C25: Equity PMS | D25: Carnelian Capital Compounder Strategy | E25: One 97 Communications | F25: ARTHYA | G25: =+VLOOKUP(E25,Summary!$E$3:$F$47,2,0) -> INE982J01020 | H25: 46185 | I25: Buy | J25: 44 | K25: 1073.1866 | L25: 47243.82
A26: DAJ | B26: Equity | C26: Equity PMS | D26: Carnelian Capital Compounder Strategy | E26: Tata Motors | F26: ARTHYA | G26: =+VLOOKUP(E26,Summary!$E$3:$F$47,2,0) -> INE1TAE01010 | H26: 46185 | I26: Buy | J26: 77 | K26: 389.1997 | L26: 29983.36
A27: DAJ | B27: Equity | C27: Equity PMS | D27: Carnelian Capital Compounder Strategy | E27: Tata Motors Passenger Vehicles | F27: ARTHYA | G27: =+VLOOKUP(E27,Summary!$E$3:$F$47,2,0) -> INE155A01022 | H27: 46185 | I27: Buy | J27: 37 | K27: 389.4824 | L27: 14418.05
A28: DAJ | B28: Equity | C28: Equity PMS | D28: Carnelian Capital Compounder Strategy | E28: Tata Technologies | F28: ARTHYA | G28: =+VLOOKUP(E28,Summary!$E$3:$F$47,2,0) -> INE142M01025 | H28: 46185 | I28: Buy | J28: 23 | K28: 760.94 | L28: 17510.37
A29: DAJ | B29: Equity | C29: Equity PMS | D29: Carnelian Capital Compounder Strategy | E29: Tata Technologies | F29: ARTHYA | G29: =+VLOOKUP(E29,Summary!$E$3:$F$47,2,0) -> INE142M01025 | H29: 46184 | I29: Buy | J29: 247 | K29: 745.9687 | L29: 184383.25
A30: DAJ | B30: Equity | C30: Equity PMS | D30: Carnelian Capital Compounder Strategy | E30: Tata Motors | F30: ARTHYA | G30: =+VLOOKUP(E30,Summary!$E$3:$F$47,2,0) -> INE1TAE01010 | H30: 46183 | I30: Buy | J30: 32 | K30: 365.7287 | L30: 11709.17
A31: DAJ | B31: Equity | C31: Equity PMS | D31: Carnelian Capital Compounder Strategy | E31: Tata Technologies | F31: ARTHYA | G31: =+VLOOKUP(E31,Summary!$E$3:$F$47,2,0) -> INE142M01025 | H31: 46183 | I31: Buy | J31: 531 | K31: 757.6995 | L31: 402579.83
A32: DAJ | B32: Equity | C32: Equity PMS | D32: Carnelian Capital Compounder Strategy | E32: GlaxoSmithkline Pharmaceuticals | F32: ARTHYA | G32: INE159A01016 | H32: 46177 | I32: Sell | J32: 85 | K32: 2167.2117 | L32: 184102.46
A33: DAJ | B33: Equity | C33: Equity PMS | D33: Carnelian Capital Compounder Strategy | E33: Tata Motors Passenger Vehicles | F33: ARTHYA | G33: =+VLOOKUP(E33,Summary!$E$3:$F$47,2,0) -> INE155A01022 | H33: 46177 | I33: Buy | J33: 742 | K33: 398.4586 | L33: 295804.1
A34: DAJ | B34: Equity | C34: Equity PMS | D34: Carnelian Capital Compounder Strategy | E34: Maruti Suzuki | F34: ARTHYA | G34: INE585B01010 | H34: 46176 | I34: Sell | J34: 44 | K34: 13100.975 | L34: 576097.03
A35: DAJ | B35: Equity | C35: Equity PMS | D35: Carnelian Capital Compounder Strategy | E35: LTM Limited | F35: ARTHYA | G35: =+VLOOKUP(E35,Summary!$E$3:$F$47,2,0) -> INE214T01019 | H35: 46174 | I35: Buy | J35: 46 | K35: 4245.5452 | L35: 195392.73
A36: DAJ | B36: Equity | C36: Equity PMS | D36: Carnelian Capital Compounder Strategy | E36: Poly Medicure | F36: ARTHYA | G36: =+VLOOKUP(E36,Summary!$E$3:$F$47,2,0) -> INE205C01021 | H36: 46174 | I36: Buy | J36: 15 | K36: 1342.0962 | L36: 20141.51
A37: DAJ | B37: Equity | C37: Equity PMS | D37: Carnelian Capital Compounder Strategy | E37: GlaxoSmithkline Pharmaceuticals | F37: ARTHYA | G37: INE159A01016 | H37: 46169 | I37: Sell | J37: 46 | K37: 2307.0193 | L37: 106069.83
A38: DAJ | B38: Equity | C38: Equity PMS | D38: Carnelian Capital Compounder Strategy | E38: Aurobindo Pharma | F38: ARTHYA | G38: =+VLOOKUP(E38,Summary!$E$3:$F$47,2,0) -> INE406A01037 | H38: 46168 | I38: Buy | J38: 2 | K38: 1455.355 | L38: 2912.17
A39: DAJ | B39: Equity | C39: Equity PMS | D39: Carnelian Capital Compounder Strategy | E39: Delhivery | F39: ARTHYA | G39: INE148O01028 | H39: 46168 | I39: Buy | J39: 489 | K39: 458.8489 | L39: 224489.29
A40: DAJ | B40: Equity | C40: Equity PMS | D40: Carnelian Capital Compounder Strategy | E40: Dr Lal Pathlabs | F40: ARTHYA | G40: =+VLOOKUP(E40,Summary!$E$3:$F$47,2,0) -> INE600L01024 | H40: 46168 | I40: Buy | J40: 3 | K40: 1618.33 | L40: 4858.07
...
